Workbook

Sheet Sheet1
A1: Woxer | G1: Date Issued
A2: Chloe Hazan | G2: 46232
A3: 6340 NE 4TH Court
A4: Miami, FL 33138 | G4: Purchase Order Number
A5: Phone: +1 305-905-9630 | G5: W22607-0-9
A7: VENDOR | G7: SHIP TO
A8: Brandix | G8: Woxer
A9: Lot 19, Block B, Biyagama EPZ, | G9: Shipmonk Warehouse
A10: Malwana, Sri Lanka | G10: 7200 Intermodal Dr
A11: Phone: +94 771853373 | G11: Louisville, KY, 40258
G12: (855) 222-4601
D14: SIZES
A15: PRODUCT | B15: STYLE # | C15: COLORWAY | D15: XS | E15: S | F15: M | G15: L | H15: XL | I15: 2XL | J15: 3XL | K15: 4XL | L15: TOTAL QTY | M15: UNIT PRICE | N15: TOTAL
A16: Baller | B16: =VLOOKUP(A16,Data!$A:$B,2,FALSE) -> W5369 | C16: Ion Drift | D16: 45 | E16: 190 | F16: 625 | G16: 675 | H16: 475 | I16: 300 | J16: 150 | K16: 45 | L16: =SUM(D16:K16) -> 2505
A17: Baller | B17: =VLOOKUP(A17,Data!$A:$B,2,FALSE) -> W5369 | C17: Deep Current 2.0 | D17: 45 | E17: 190 | F17: 625 | G17: 675 | H17: 475 | I17: 300 | J17: 150 | K17: 45 | L17: =SUM(D17:K17) -> 2505
A18: Baller | B18: =VLOOKUP(A18,Data!$A:$B,2,FALSE) -> W5369 | C18: Stars Rain | D18: 30 | E18: 135 | F18: 440 | G18: 475 | H18: 335 | I18: 210 | J18: 105 | K18: 35 | L18: =SUM(D18:K18) -> 1765
A19: Baller | B19: =VLOOKUP(A19,Data!$A:$B,2,FALSE) -> W5369 | C19: Violet Bang | D19: 30 | E19: 135 | F19: 440 | G19: 475 | H19: 335 | I19: 210 | J19: 105 | K19: 35 | L19: =SUM(D19:K19) -> 1765
A20: Baller | B20: =VLOOKUP(A20,Data!$A:$B,2,FALSE) -> W5369 | C20: Moon Field | D20: 25 | E20: 105 | F20: 345 | G20: 375 | H20: 265 | I20: 165 | J20: 85 | K20: 25 | L20: =SUM(D20:K20) -> 1390
A21: Baller | B21: =VLOOKUP(A21,Data!$A:$B,2,FALSE) -> W5369 | C21: Star Noise | D21: 25 | E21: 105 | F21: 345 | G21: 375 | H21: 265 | I21: 165 | J21: 85 | K21: 25 | L21: =SUM(D21:K21) -> 1390
A22: Baller | B22: =VLOOKUP(A22,Data!$A:$B,2,FALSE) -> W5369 | C22: Galactic River | D22: 30 | E22: 125 | F22: 410 | G22: 440 | H22: 310 | I22: 195 | J22: 100 | K22: 30 | L22: =SUM(D22:K22) -> 1640
A24: Star | B24: =VLOOKUP(A24,Data!$A:$B,2,FALSE) -> W5355 | C24: Ion Drift | D24: 55 | E24: 210 | F24: 380 | G24: 365 | H24: 170 | I24: 95 | J24: 40 | L24: =SUM(D24:K24) -> 1315
A25: Star | B25: =VLOOKUP(A25,Data!$A:$B,2,FALSE) -> W5355 | C25: Deep Current 2.0 | D25: 55 | E25: 210 | F25: 380 | G25: 365 | H25: 170 | I25: 95 | J25: 40 | L25: =SUM(D25:K25) -> 1315
A26: Star | B26: =VLOOKUP(A26,Data!$A:$B,2,FALSE) -> W5355 | C26: Stars Rain | D26: 40 | E26: 150 | F26: 265 | G26: 255 | H26: 120 | I26: 65 | J26: 30 | L26: =SUM(D26:K26) -> 925
A27: Star | B27: =VLOOKUP(A27,Data!$A:$B,2,FALSE) -> W5355 | C27: Violet Bang | D27: 40 | E27: 150 | F27: 265 | G27: 255 | H27: 120 | I27: 65 | J27: 30 | L27: =SUM(D27:K27) -> 925
A28: Star | B28: =VLOOKUP(A28,Data!$A:$B,2,FALSE) -> W5355 | C28: Moon Field | D28: 30 | E28: 115 | F28: 210 | G28: 200 | H28: 95 | I28: 50 | J28: 25 | L28: =SUM(D28:K28) -> 725
A29: Star | B29: =VLOOKUP(A29,Data!$A:$B,2,FALSE) -> W5355 | C29: Star Noise | D29: 30 | E29: 115 | F29: 210 | G29: 200 | H29: 95 | I29: 50 | J29: 25 | L29: =SUM(D29:K29) -> 725
A30: Star | B30: =VLOOKUP(A30,Data!$A:$B,2,FALSE) -> W5355 | C30: Galactic River | D30: 35 | E30: 145 | F30: 260 | G30: 250 | H30: 115 | I30: 65 | J30: 30 | L30: =SUM(D30:K30) -> 900
A32: Biker | B32: =VLOOKUP(A32,Data!$A:$B,2,FALSE) -> W5333 | C32: Ion Drift | E32: 30 | F32: 90 | G32: 145 | H32: 160 | I32: 85 | J32: 60 | K32: 40 | L32: =SUM(D32:K32) -> 610
A33: Biker | B33: =VLOOKUP(A33,Data!$A:$B,2,FALSE) -> W5333 | C33: Deep Current 2.0 | E33: 30 | F33: 90 | G33: 145 | H33: 160 | I33: 85 | J33: 60 | K33: 40 | L33: =SUM(D33:K33) -> 610
A34: Biker | B34: =VLOOKUP(A34,Data!$A:$B,2,FALSE) -> W5333 | C34: Stars Rain | E34: 20 | F34: 65 | G34: 105 | H34: 115 | I34: 60 | J34: 45 | K34: 25 | L34: =SUM(D34:K34) -> 435
A35: Biker | B35: =VLOOKUP(A35,Data!$A:$B,2,FALSE) -> W5333 | C35: Violet Bang | E35: 20 | F35: 65 | G35: 105 | H35: 115 | I35: 60 | J35: 45 | K35: 25 | L35: =SUM(D35:K35) -> 435
A36: Biker | B36: =VLOOKUP(A36,Data!$A:$B,2,FALSE) -> W5333 | C36: Moon Field | E36: 15 | F36: 50 | G36: 80 | H36: 90 | I36: 50 | J36: 35 | K36: 20 | L36: =SUM(D36:K36) -> 340
A37: Biker | B37: =VLOOKUP(A37,Data!$A:$B,2,FALSE) -> W5333 | C37: Star Noise | E37: 15 | F37: 50 | G37: 80 | H37: 90 | I37: 50 | J37: 35 | K37: 20 | L37: =SUM(D37:K37) -> 340
A38: Biker | B38: =VLOOKUP(A38,Data!$A:$B,2,FALSE) -> W5333 | C38: Galactic River | E38: 15 | F38: 50 | G38: 80 | H38: 90 | I38: 50 | J38: 35 | K38: 20 | L38: =SUM(D38:K38) -> 340
A40: Baller HW | B40: =VLOOKUP(A40,Data!$A:$B,2,FALSE) -> W5091 | C40: Ion Drift | E40: 30 | F40: 100 | G40: 130 | H40: 105 | I40: 75 | J40: 40 | K40: 25 | L40: =SUM(D40:K40) -> 505
A41: Baller HW | B41: =VLOOKUP(A41,Data!$A:$B,2,FALSE) -> W5091 | C41: Deep Current 2.0 | E41: 30 | F41: 100 | G41: 130 | H41: 105 | I41: 75 | J41: 40 | K41: 25 | L41: =SUM(D41:K41) -> 505
A42: Baller HW | B42: =VLOOKUP(A42,Data!$A:$B,2,FALSE) -> W5091 | C42: Stars Rain | E42: 25 | F42: 70 | G42: 95 | H42: 75 | I42: 55 | J42: 30 | K42: 20 | L42: =SUM(D42:K42) -> 370
A43: Baller HW | B43: =VLOOKUP(A43,Data!$A:$B,2,FALSE) -> W5091 | C43: Violet Bang | E43: 25 | F43: 70 | G43: 95 | H43: 75 | I43: 55 | J43: 30 | K43: 20 | L43: =SUM(D43:K43) -> 370
A44: Baller HW | B44: =VLOOKUP(A44,Data!$A:$B,2,FALSE) -> W5091 | C44: Moon Field | E44: 20 | F44: 55 | G44: 75 | H44: 60 | I44: 40 | J44: 25 | K44: 15 | L44: =SUM(D44:K44) -> 290
... A46: Baller HW | B46: =VLOOKUP(A46,Data!$A:$B,2,FALSE) -> W5091 | C46: Galactic River | E46: 20 | F46: 55 | G46: 75 | H46: 60 | I46: 40 | J46: 25 | K46: 15 | L46: =SUM(D46:K46) -> 290
...

Sheet Data
A1: Style | B1: Style Code | C1: Item Abrv | D1: Style Abrv | F1: Style | G1: Color type | H1: FOB | K1: Color Name | L1: Color Type | O1: Size | P1: Size Code | R1: CONCAT(VLOOKUP(F34,Data!A:D,3,FALSE),VLOOKUP(F34,Data!A:D,4,FALSE),"-",VLOOKUP(C34,Data!K:M,3,FALSE),VLOOKUP(G34,Data!O:P,2,FALSE))
A2: Baller | B2: W5369 | C2: Z8 | D2: BA | F2: Baller | G2: Solid | H2: 3.46 | K2: Black Marl | L2: Solid | O2: XS | P2: 0-XS
A3: Star | B3: W5355 | C3: Z8 | D3: ST | F3: Baller | G3: Heather Grey | H3: 3.6 | K3: Black Tie Dye | L3: Solid | O3: S | P3: 1-S | R3: Vendor | S3: Address | T3: PO Number Start
A4: Biker | B4: W5333 | C4: Z8 | D4: BI | F4: Baller | G4: Charcoal Heather | H4: 3.63 | K4: Monochrome | L4: Solid | O4: M | P4: 2-M | R4: Brandix | S4: Lot 19, Block B, Biyagama EPZ, Malwana, Sri Lanka Phone: +94 771853373 | T4: W2
A5: Baller HW | B5: W5091 | C5: Z8 | D5: HI | F5: Baller | G5: Print Screen/Rotary | H5: 3.54 | K5: Black Remix | L5: Solid | O5: L | P5: 3-L | R5: I Apparel | S5: National Road 3, KM27, in Kandal Steng, Kandal Province, Cambodia Phone: +855 070298722 | T5: W3
A6: Star HW | B6: W5250 | C6: Z8 | D6: SH | F6: Baller | G6: Digital Prints | H6: 3.94 | K6: Garnet | L6: Solid | O6: XL | P6: 4-XL | R6: Delta Galil | S6: 45 Ha’Eshel St., Southern Industrial Zone Caesarea, 3088900, Israel Office: +972-76-8177099 | T6: W4
A7: Bold | B7: W4540 | C7: Z8 | D7: GS | F7: Baller | G7: Pigment Discharge | K7: Agate | L7: Solid | O7: 2XL | P7: 5-2X
A8: Classic | B8: W4828 | C8: Z8 | D8: BR | F8: Star | G8: Solid | H8: 3.07 | K8: Malachite | L8: Solid | O8: 3XL | P8: 6-3X
A9: Bikini | B9: W4060 | C9: Z8 | D9: BK | F9: Star | G9: Heather Grey | H9: 3.18 | K9: Silver | L9: Solid | O9: 4XL | P9: 7-4X
A10: Boss | B10: W5055 | C10: B8 | D10: BO | F10: Star | G10: Charcoal Heather | H10: 3.21 | K10: Black Pearl | L10: Solid | T10: Brandix
A11: Icon | B11: W5075 | C11: B8 | D11: IC | F11: Star | G11: Print Screen/Rotary | H11: 3.22 | K11: Brushed Gold | L11: Solid | T11: Lot 19, Block B, Biyagama EPZ,
A12: Dreamer | B12: W5555 | C12: Z8 | D12: DR | F12: Star | G12: Digital Prints | H12: 3.5 | K12: Lemon-Lime | L12: Solid | T12: Malwana, Sri Lanka
A13: Boss 2.0 | B13: BR2022 | C13: B8 | D13: SP | F13: Star | G13: Pigment Discharge | K13: Spearmint | L13: Solid | T13: Phone: +94 771853373
A14: Baller Flex | B14: U1001 | C14: Z8 | F14: Biker | G14: Solid | H14: 3.81 | K14: Berry | L14: Solid
A15: Boss Flex | B15: BR2024 | C15: Z8 | F15: Biker | G15: Heather Grey | H15: 3.85 | K15: Tonal-Blue | L15: Solid | T15: I Apparel
A16: Biker Flex | B16: U1023 | C16: Z8 | F16: Biker | G16: Charcoal Heather | H16: 3.88 | K16: Khaki | L16: Solid | T16: National Road 3, KM27, in Kandal Steng,
A17: Icon 2.0 | B17: BR2023 | C17: B8 | D17: IP | F17: Biker | G17: Print Screen/Rotary | H17: 3.99 | K17: Blushing | L17: Solid | T17: Kandal Province, Cambodia
A18: Rib Tank | B18: T3006 | C18: Z8 | D18: TK | F18: Biker | G18: Digital Prints | H18: 4.49 | K18: Grassy Stripe | L18: Solid | T18: Phone: +855 070298722
A19: Baller Rib | B19: U1000 | C19: Z8 | D19: RB | F19: Biker | G19: Pigment Discharge | K19: Linen | L19: Solid
A20: Biker HW | B20: W5341 | C20: Z8 | D20: BH | F20: Baller HW | G20: Solid | H20: 4.07 | K20: Shirting Stripe | L20: Solid | T20: Delta Galil
A21: Baller Fly 5" | B21: U1019 | C21: Z8 | F21: Baller HW | G21: Heather Grey | H21: 4.35 | K21: Embers | L21: Solid | T21: 45 Ha’Eshel St., Southern Industrial Zone
A22: Baller Fly 7" | B22: U1024 | C22: Z8 | F22: Baller HW | G22: Charcoal Heather | H22: 4.61 | K22: Halloween Black | L22: Solid | T22: Caesarea, 3088900, Israel
A23: Baller Luxe | B23: U1003 | C23: Z8 | F23: Baller HW | G23: Print Screen/Rotary | H23: 4.46 | K23: Eerie | L23: Solid | T23: Office: +972-76-8177099
A24: Bold Luxe | B24: U1004 | C24: Z8 | F24: Baller HW | G24: Digital Prints | H24: 5.07 | K24: Rock Candy | L24: Solid
A25: Bralette Luxe | B25: BR2014 | C25: Z8 | F25: Baller HW | G25: Pigment Discharge | K25: Eerie-Exclusive | L25: Solid
A26: Woven Shorts | B26: U1025 | C26: Z8 | F26: Dreamer | G26: Solid | H26: 6.42 | K26: Hi-Vis | L26: Solid
A27: Baller Pad Liner | B27: U1007 | C27: Z7 | F27: Dreamer | G27: Heather Grey | H27: 6.93 | K27: Brushed Camo | L27: Solid
A28: HeadBand | B28: A6000 | C28: H7 | D28: PL | F28: Dreamer | G28: Charcoal Heather | H28: 7.2 | K28: Ginger | L28: Solid
A29: Baller Swim | B29: BT4010 | D29: HB | F29: Dreamer | G29: Print Screen/Rotary | H29: 7.21 | K29: Black Chrome | L29: Solid
A30: Bikini Swim | B30: BT4012 | F30: Dreamer | G30: Digital Prints | H30: 8.01 | K30: Artic | L30: Solid
A31: Boss Swim | B31: T3010 | F31: Dreamer | G31: Pigment Discharge | K31: Peppermint | L31: Solid
A32: Boxy Tee | B32: T3020 | F32: Star HW | G32: Solid | K32: Oatmeal Heather | L32: Solid
A33: Boxy Tank | B33: T3021 | F33: Star HW | G33: Heather Grey | K33: Fair Isle | L33: Solid
A34: Rib Crop Tank | B34: T3017 | F34: Star HW | G34: Charcoal Heather | K34: Frost Plaid | L34: Solid
A35: Wide Elastic Boxer | B35: BT4017 | F35: Star HW | G35: Print Screen/Rotary | K35: Cabin Plaid | L35: Solid
A36: Wide Elastic Boxer 7" | B36: BT4018 | F36: Star HW | G36: Digital Prints | K36: Vintage Navy | L36: Solid
A37: Strech Woven Short | B37: BT4006 | F37: Star HW | G37: Pigment Discharge | K37: Pine | L37: Solid
A38: SS Sleep Tee | B38: T3030 | F38: Bold | G38: Solid | H38: 3.64 | K38: Cardinal | L38: Solid
A39: Sleep Jogger | B39: BT4027 | F39: Bold | G39: Heather Grey | H39: 3.73 | K39: B&W Plaid | L39: Solid
A40: Sleep Short | B40: BT4026 | F40: Bold | G40: Charcoal Heather | H40: 3.9 | K40: Frost | L40: Solid
...
